Workbook

Sheet Start
A1: CaseMetrology | OAL screening — mixed bag / bin
A3: 1. Save this .xlsx locally. Light-blue cells are entry fields; gray cells are fixed values or formulas.
A4: 2. Sessions: use one new row per session. Enter a unique session ID, date and actual start/end timestamps.
A5: 3. Record five pre-check and five post-check readings, removing and repositioning the block each time.
A6: 4. Take any case from the bag. On the next row enter B (etched ID), C (verified), D (inches), F (time), I (session), P (notes).
A7: 5. Date, operator and reference means fill from the matching session. Do not edit a completed session to start another.
A8: 6. Put each measured case in a separate tray. Preserve all readings; leave selection/classification decisions for review.
A9: 7. Record temperatures, times, units, meter/probe identities and abnormalities in session notes or the existing environment record.
A10: 8. Numerical checks below are not authorization. Enter session_status only after the required human review.
A11: 9. Save .xlsx often. Return it here for CSV export and Nano audit; no macros or automatic timestamps are used.
A12: Rows record actual collection order, not a preset ID order. Do not sort or edit gray cells. Sheets are not locked.
A14: Fixed reference / rule | B14: Value | D14: Progress / entry checks
A15: Operator | B15: Timmy D. Bell | D15: Numeric readings | E15: =COUNT(Screening!D2:D236) -> 235
A16: Caliper serial | B16: B24254849 | D16: IDs still unmeasured | E16: =COUNTIF(G48:G282,0) -> 0
A17: Certified reference (in) | B17: 1.0000024 | D17: Rows needing attention | E17: =COUNTIF(C48:C282,"REVIEW") -> 0
A18: Expected display (in) | B18: 1 | D18: Duplicate-ID rows | E18: =COUNTIF(B48:B282,"DUPLICATE") -> 0
A19: E_limit (in) | B19: 0.0005 | D19: Sequence changes | E19: =COUNTIF(D48:D282,"CHANGED") -> 0
A20: R_limit (in) | B20: 0.0005 | D20: Order: screening protocol 2026-08-09, sections 2 and 4 (any/arbitrary order), supplied by operator. CSV columns retained. Limits: d66085e. Caliper DDJ25P23P; block 253568 / T26A06624. Earlier pre-use readings are not copied into screening sessions.
A21: D_limit (in) | B21: 0.0005
A22: Readings per check | B22: 5
A24: Session ID | B24: Pre E (in) | C24: Post E (in) | D24: Drift (in) | E24: Pre numerical | F24: Post numerical | G24: Overall numerical | H24: Entry / review
A25: =IF(Sessions!A2="","",Sessions!A2) -> 1 | B25: =IF(Sessions!M2="","",Sessions!M2-$B$18) -> 0 | C25: =IF(Sessions!T2="","",Sessions!T2-$B$18) -> 0 | D25: =IF(AND(ISNUMBER(B25),ISNUMBER(C25)),Sessions!T2-Sessions!M2,"") -> 0 | E25: =IF(A25="","",IF(NOT(ISNUMBER(B25)),"INCOMPLETE",IF(AND(ROUND(ABS(B25),10)<=$B$19,ROUND(Sessions!N2,10)<=$B$20),"WITHIN LIMITS","FAIL"))) -> WITHIN LIMITS | F25: =IF(A25="","",IF(NOT(ISNUMBER(C25)),"INCOMPLETE",IF(AND(ROUND(ABS(C25),10)<=$B$19,ROUND(Sessions!U2,10)<=$B$20),"WITHIN LIMITS","FAIL"))) -> WITHIN LIMITS | G25: =IF(A25="","",IF(OR(E25="FAIL",F25="FAIL"),"FAIL",IF(NOT(ISNUMBER(D25)),"INCOMPLETE",IF(ROUND(ABS(D25),10)<=$B$21,"WITHIN LIMITS","FAIL")))) -> WITHIN LIMITS | H25: =IF(A25="","",IF(COUNTIF(Sessions!$A$2:$A$21,A25)<>1,"DUPLICATE ID",IF(OR(Sessions!B2="",Sessions!C2="",Sessions!D2="",Sessions!V2=""),"REVIEW PENDING","AUDIT REQUIRED"))) -> REVIEW PENDING
A26: =IF(Sessions!A3="","",Sessions!A3) | B26: =IF(Sessions!M3="","",Sessions!M3-$B$18) | C26: =IF(Sessions!T3="","",Sessions!T3-$B$18) | D26: =IF(AND(ISNUMBER(B26),ISNUMBER(C26)),Sessions!T3-Sessions!M3,"") | E26: =IF(A26="","",IF(NOT(ISNUMBER(B26)),"INCOMPLETE",IF(AND(ROUND(ABS(B26),10)<=$B$19,ROUND(Sessions!N3,10)<=$B$20),"WITHIN LIMITS","FAIL"))) | F26: =IF(A26="","",IF(NOT(ISNUMBER(C26)),"INCOMPLETE",IF(AND(ROUND(ABS(C26),10)<=$B$19,ROUND(Sessions!U3,10)<=$B$20),"WITHIN LIMITS","FAIL"))) | G26: =IF(A26="","",IF(OR(E26="FAIL",F26="FAIL"),"FAIL",IF(NOT(ISNUMBER(D26)),"INCOMPLETE",IF(ROUND(ABS(D26),10)<=$B$21,"WITHIN LIMITS","FAIL")))) | H26: =IF(A26="","",IF(COUNTIF(Sessions!$A$2:$A$21,A26)<>1,"DUPLICATE ID",IF(OR(Sessions!B3="",Sessions!C3="",Sessions!D3="",Sessions!V3=""),"REVIEW PENDING","AUDIT REQUIRED")))
A27: =IF(Sessions!A4="","",Sessions!A4) | B27: =IF(Sessions!M4="","",Sessions!M4-$B$18) | C27: =IF(Sessions!T4="","",Sessions!T4-$B$18) | D27: =IF(AND(ISNUMBER(B27),ISNUMBER(C27)),Sessions!T4-Sessions!M4,"") | E27: =IF(A27="","",IF(NOT(ISNUMBER(B27)),"INCOMPLETE",IF(AND(ROUND(ABS(B27),10)<=$B$19,ROUND(Sessions!N4,10)<=$B$20),"WITHIN LIMITS","FAIL"))) | F27: =IF(A27="","",IF(NOT(ISNUMBER(C27)),"INCOMPLETE",IF(AND(ROUND(ABS(C27),10)<=$B$19,ROUND(Sessions!U4,10)<=$B$20),"WITHIN LIMITS","FAIL"))) | G27: =IF(A27="","",IF(OR(E27="FAIL",F27="FAIL"),"FAIL",IF(NOT(ISNUMBER(D27)),"INCOMPLETE",IF(ROUND(ABS(D27),10)<=$B$21,"WITHIN LIMITS","FAIL")))) | H27: =IF(A27="","",IF(COUNTIF(Sessions!$A$2:$A$21,A27)<>1,"DUPLICATE ID",IF(OR(Sessions!B4="",Sessions!C4="",Sessions!D4="",Sessions!V4=""),"REVIEW PENDING","AUDIT REQUIRED")))
A28: =IF(Sessions!A5="","",Sessions!A5) | B28: =IF(Sessions!M5="","",Sessions!M5-$B$18) | C28: =IF(Sessions!T5="","",Sessions!T5-$B$18) | D28: =IF(AND(ISNUMBER(B28),ISNUMBER(C28)),Sessions!T5-Sessions!M5,"") | E28: =IF(A28="","",IF(NOT(ISNUMBER(B28)),"INCOMPLETE",IF(AND(ROUND(ABS(B28),10)<=$B$19,ROUND(Sessions!N5,10)<=$B$20),"WITHIN LIMITS","FAIL"))) | F28: =IF(A28="","",IF(NOT(ISNUMBER(C28)),"INCOMPLETE",IF(AND(ROUND(ABS(C28),10)<=$B$19,ROUND(Sessions!U5,10)<=$B$20),"WITHIN LIMITS","FAIL"))) | G28: =IF(A28="","",IF(OR(E28="FAIL",F28="FAIL"),"FAIL",IF(NOT(ISNUMBER(D28)),"INCOMPLETE",IF(ROUND(ABS(D28),10)<=$B$21,"WITHIN LIMITS","FAIL")))) | H28: =IF(A28="","",IF(COUNTIF(Sessions!$A$2:$A$21,A28)<>1,"DUPLICATE ID",IF(OR(Sessions!B5="",Sessions!C5="",Sessions!D5="",Sessions!V5=""),"REVIEW PENDING","AUDIT REQUIRED")))
A29: =IF(Sessions!A6="","",Sessions!A6) | B29: =IF(Sessions!M6="","",Sessions!M6-$B$18) | C29: =IF(Sessions!T6="","",Sessions!T6-$B$18) | D29: =IF(AND(ISNUMBER(B29),ISNUMBER(C29)),Sessions!T6-Sessions!M6,"") | E29: =IF(A29="","",IF(NOT(ISNUMBER(B29)),"INCOMPLETE",IF(AND(ROUND(ABS(B29),10)<=$B$19,ROUND(Sessions!N6,10)<=$B$20),"WITHIN LIMITS","FAIL"))) | F29: =IF(A29="","",IF(NOT(ISNUMBER(C29)),"INCOMPLETE",IF(AND(ROUND(ABS(C29),10)<=$B$19,ROUND(Sessions!U6,10)<=$B$20),"WITHIN LIMITS","FAIL"))) | G29: =IF(A29="","",IF(OR(E29="FAIL",F29="FAIL"),"FAIL",IF(NOT(ISNUMBER(D29)),"INCOMPLETE",IF(ROUND(ABS(D29),10)<=$B$21,"WITHIN LIMITS","FAIL")))) | H29: =IF(A29="","",IF(COUNTIF(Sessions!$A$2:$A$21,A29)<>1,"DUPLICATE ID",IF(OR(Sessions!B6="",Sessions!C6="",Sessions!D6="",Sessions!V6=""),"REVIEW PENDING","AUDIT REQUIRED")))
A30: =IF(Sessions!A7="","",Sessions!A7) | B30: =IF(Sessions!M7="","",Sessions!M7-$B$18) | C30: =IF(Sessions!T7="","",Sessions!T7-$B$18) | D30: =IF(AND(ISNUMBER(B30),ISNUMBER(C30)),Sessions!T7-Sessions!M7,"") | E30: =IF(A30="","",IF(NOT(ISNUMBER(B30)),"INCOMPLETE",IF(AND(ROUND(ABS(B30),10)<=$B$19,ROUND(Sessions!N7,10)<=$B$20),"WITHIN LIMITS","FAIL"))) | F30: =IF(A30="","",IF(NOT(ISNUMBER(C30)),"INCOMPLETE",IF(AND(ROUND(ABS(C30),10)<=$B$19,ROUND(Sessions!U7,10)<=$B$20),"WITHIN LIMITS","FAIL"))) | G30: =IF(A30="","",IF(OR(E30="FAIL",F30="FAIL"),"FAIL",IF(NOT(ISNUMBER(D30)),"INCOMPLETE",IF(ROUND(ABS(D30),10)<=$B$21,"WITHIN LIMITS","FAIL")))) | H30: =IF(A30="","",IF(COUNTIF(Sessions!$A$2:$A$21,A30)<>1,"DUPLICATE ID",IF(OR(Sessions!B7="",Sessions!C7="",Sessions!D7="",Sessions!V7=""),"REVIEW PENDING","AUDIT REQUIRED")))
A31: =IF(Sessions!A8="","",Sessions!A8) | B31: =IF(Sessions!M8="","",Sessions!M8-$B$18) | C31: =IF(Sessions!T8="","",Sessions!T8-$B$18) | D31: =IF(AND(ISNUMBER(B31),ISNUMBER(C31)),Sessions!T8-Sessions!M8,"") | E31: =IF(A31="","",IF(NOT(ISNUMBER(B31)),"INCOMPLETE",IF(AND(ROUND(ABS(B31),10)<=$B$19,ROUND(Sessions!N8,10)<=$B$20),"WITHIN LIMITS","FAIL"))) | F31: =IF(A31="","",IF(NOT(ISNUMBER(C31)),"INCOMPLETE",IF(AND(ROUND(ABS(C31),10)<=$B$19,ROUND(Sessions!U8,10)<=$B$20),"WITHIN LIMITS","FAIL"))) | G31: =IF(A31="","",IF(OR(E31="FAIL",F31="FAIL"),"FAIL",IF(NOT(ISNUMBER(D31)),"INCOMPLETE",IF(ROUND(ABS(D31),10)<=$B$21,"WITHIN LIMITS","FAIL")))) | H31: =IF(A31="","",IF(COUNTIF(Sessions!$A$2:$A$21,A31)<>1,"DUPLICATE ID",IF(OR(Sessions!B8="",Sessions!C8="",Sessions!D8="",Sessions!V8=""),"REVIEW PENDING","AUDIT REQUIRED")))
A32: =IF(Sessions!A9="","",Sessions!A9) | B32: =IF(Sessions!M9="","",Sessions!M9-$B$18) | C32: =IF(Sessions!T9="","",Sessions!T9-$B$18) | D32: =IF(AND(ISNUMBER(B32),ISNUMBER(C32)),Sessions!T9-Sessions!M9,"") | E32: =IF(A32="","",IF(NOT(ISNUMBER(B32)),"INCOMPLETE",IF(AND(ROUND(ABS(B32),10)<=$B$19,ROUND(Sessions!N9,10)<=$B$20),"WITHIN LIMITS","FAIL"))) | F32: =IF(A32="","",IF(NOT(ISNUMBER(C32)),"INCOMPLETE",IF(AND(ROUND(ABS(C32),10)<=$B$19,ROUND(Sessions!U9,10)<=$B$20),"WITHIN LIMITS","FAIL"))) | G32: =IF(A32="","",IF(OR(E32="FAIL",F32="FAIL"),"FAIL",IF(NOT(ISNUMBER(D32)),"INCOMPLETE",IF(ROUND(ABS(D32),10)<=$B$21,"WITHIN LIMITS","FAIL")))) | H32: =IF(A32="","",IF(COUNTIF(Sessions!$A$2:$A$21,A32)<>1,"DUPLICATE ID",IF(OR(Sessions!B9="",Sessions!C9="",Sessions!D9="",Sessions!V9=""),"REVIEW PENDING","AUDIT REQUIRED")))
A33: =IF(Sessions!A10="","",Sessions!A10) | B33: =IF(Sessions!M10="","",Sessions!M10-$B$18) | C33: =IF(Sessions!T10="","",Sessions!T10-$B$18) | D33: =IF(AND(ISNUMBER(B33),ISNUMBER(C33)),Sessions!T10-Sessions!M10,"") | E33: =IF(A33="","",IF(NOT(ISNUMBER(B33)),"INCOMPLETE",IF(AND(ROUND(ABS(B33),10)<=$B$19,ROUND(Sessions!N10,10)<=$B$20),"WITHIN LIMITS","FAIL"))) | F33: =IF(A33="","",IF(NOT(ISNUMBER(C33)),"INCOMPLETE",IF(AND(ROUND(ABS(C33),10)<=$B$19,ROUND(Sessions!U10,10)<=$B$20),"WITHIN LIMITS","FAIL"))) | G33: =IF(A33="","",IF(OR(E33="FAIL",F33="FAIL"),"FAIL",IF(NOT(ISNUMBER(D33)),"INCOMPLETE",IF(ROUND(ABS(D33),10)<=$B$21,"WITHIN LIMITS","FAIL")))) | H33: =IF(A33="","",IF(COUNTIF(Sessions!$A$2:$A$21,A33)<>1,"DUPLICATE ID",IF(OR(Sessions!B10="",Sessions!C10="",Sessions!D10="",Sessions!V10=""),"REVIEW PENDING","AUDIT REQUIRED")))
A34: =IF(Sessions!A11="","",Sessions!A11) | B34: =IF(Sessions!M11="","",Sessions!M11-$B$18) | C34: =IF(Sessions!T11="","",Sessions!T11-$B$18) | D34: =IF(AND(ISNUMBER(B34),ISNUMBER(C34)),Sessions!T11-Sessions!M11,"") | E34: =IF(A34="","",IF(NOT(ISNUMBER(B34)),"INCOMPLETE",IF(AND(ROUND(ABS(B34),10)<=$B$19,ROUND(Sessions!N11,10)<=$B$20),"WITHIN LIMITS","FAIL"))) | F34: =IF(A34="","",IF(NOT(ISNUMBER(C34)),"INCOMPLETE",IF(AND(ROUND(ABS(C34),10)<=$B$19,ROUND(Sessions!U11,10)<=$B$20),"WITHIN LIMITS","FAIL"))) | G34: =IF(A34="","",IF(OR(E34="FAIL",F34="FAIL"),"FAIL",IF(NOT(ISNUMBER(D34)),"INCOMPLETE",IF(ROUND(ABS(D34),10)<=$B$21,"WITHIN LIMITS","FAIL")))) | H34: =IF(A34="","",IF(COUNTIF(Sessions!$A$2:$A$21,A34)<>1,"DUPLICATE ID",IF(OR(Sessions!B11="",Sessions!C11="",Sessions!D11="",Sessions!V11=""),"REVIEW PENDING","AUDIT REQUIRED")))
A35: =IF(Sessions!A12="","",Sessions!A12) | B35: =IF(Sessions!M12="","",Sessions!M12-$B$18) | C35: =IF(Sessions!T12="","",Sessions!T12-$B$18) | D35: =IF(AND(ISNUMBER(B35),ISNUMBER(C35)),Sessions!T12-Sessions!M12,"") | E35: =IF(A35="","",IF(NOT(ISNUMBER(B35)),"INCOMPLETE",IF(AND(ROUND(ABS(B35),10)<=$B$19,ROUND(Sessions!N12,10)<=$B$20),"WITHIN LIMITS","FAIL"))) | F35: =IF(A35="","",IF(NOT(ISNUMBER(C35)),"INCOMPLETE",IF(AND(ROUND(ABS(C35),10)<=$B$19,ROUND(Sessions!U12,10)<=$B$20),"WITHIN LIMITS","FAIL"))) | G35: =IF(A35="","",IF(OR(E35="FAIL",F35="FAIL"),"FAIL",IF(NOT(ISNUMBER(D35)),"INCOMPLETE",IF(ROUND(ABS(D35),10)<=$B$21,"WITHIN LIMITS","FAIL")))) | H35: =IF(A35="","",IF(COUNTIF(Sessions!$A$2:$A$21,A35)<>1,"DUPLICATE ID",IF(OR(Sessions!B12="",Sessions!C12="",Sessions!D12="",Sessions!V12=""),"REVIEW PENDING","AUDIT REQUIRED")))
A36: =IF(Sessions!A13="","",Sessions!A13) | B36: =IF(Sessions!M13="","",Sessions!M13-$B$18) | C36: =IF(Sessions!T13="","",Sessions!T13-$B$18) | D36: =IF(AND(ISNUMBER(B36),ISNUMBER(C36)),Sessions!T13-Sessions!M13,"") | E36: =IF(A36="","",IF(NOT(ISNUMBER(B36)),"INCOMPLETE",IF(AND(ROUND(ABS(B36),10)<=$B$19,ROUND(Sessions!N13,10)<=$B$20),"WITHIN LIMITS","FAIL"))) | F36: =IF(A36="","",IF(NOT(ISNUMBER(C36)),"INCOMPLETE",IF(AND(ROUND(ABS(C36),10)<=$B$19,ROUND(Sessions!U13,10)<=$B$20),"WITHIN LIMITS","FAIL"))) | G36: =IF(A36="","",IF(OR(E36="FAIL",F36="FAIL"),"FAIL",IF(NOT(ISNUMBER(D36)),"INCOMPLETE",IF(ROUND(ABS(D36),10)<=$B$21,"WITHIN LIMITS","FAIL")))) | H36: =IF(A36="","",IF(COUNTIF(Sessions!$A$2:$A$21,A36)<>1,"DUPLICATE ID",IF(OR(Sessions!B13="",Sessions!C13="",Sessions!D13="",Sessions!V13=""),"REVIEW PENDING","AUDIT REQUIRED")))
... A44: =IF(Sessions!A21="","",Sessions!A21) | B44: =IF(Sessions!M21="","",Sessions!M21-$B$18) | C44: =IF(Sessions!T21="","",Sessions!T21-$B$18) | D44: =IF(AND(ISNUMBER(B44),ISNUMBER(C44)),Sessions!T21-Sessions!M21,"") | E44: =IF(A44="","",IF(NOT(ISNUMBER(B44)),"INCOMPLETE",IF(AND(ROUND(ABS(B44),10)<=$B$19,ROUND(Sessions!N21,10)<=$B$20),"WITHIN LIMITS","FAIL"))) | F44: =IF(A44="","",IF(NOT(ISNUMBER(C44)),"INCOMPLETE",IF(AND(ROUND(ABS(C44),10)<=$B$19,ROUND(Sessions!U21,10)<=$B$20),"WITHIN LIMITS","FAIL"))) | G44: =IF(A44="","",IF(OR(E44="FAIL",F44="FAIL"),"FAIL",IF(NOT(ISNUMBER(D44)),"INCOMPLETE",IF(ROUND(ABS(D44),10)<=$B$21,"WITHIN LIMITS","FAIL")))) | H44: =IF(A44="","",IF(COUNTIF(Sessions!$A$2:$A$21,A44)<>1,"DUPLICATE ID",IF(OR(Sessions!B21="",Sessions!C21="",Sessions!D21="",Sessions!V21=""),"REVIEW PENDING","AUDIT REQUIRED")))
A47: Entry sequence | B47: ID check | C47: Entry flag | D47: Sequence check | F47: Expected ID | G47: Numeric readings for ID | H47: Numeric entry indicator
A48: 1 | B48: =IF(AND(LEN(Screening!B2)=0,LEN(Screening!D2)=0),"",IF(LEN(Screening!B2)=0,"MISSING",IF(OR(NOT(ISNUMBER(Screening!B2)),COUNTIF($F$48:$F$282,Screening!B2)<>1),"INVALID",IF(COUNTIF(Screening!$B$2:$B$236,Screening!B2)>1,"DUPLICATE","OK")))) -> OK | C48: =IF(AND(LEN(Screening!B2)=0,LEN(Screening!D2)=0),"",IF(AND(B48="OK",ISNUMBER(Screening!D2),Screening!C2="yes",Screening!F2<>"",COUNTIF(Sessions!$A$2:$A$21,Screening!I2)=1,Screening!E2<>"",Screening!G2<>"",Screening!H2=$B$16),"OK","REVIEW")) -> OK | D48: =IF(A48=Screening!A2,"OK","CHANGED") -> OK | F48: 1 | G48: =SUMIF(Screening!$B$2:$B$236,F48,$H$48:$H$282) -> 1 | H48: =IF(ISNUMBER(Screening!D2),1,0) -> 1
A49: 2 | B49: =IF(AND(LEN(Screening!B3)=0,LEN(Screening!D3)=0),"",IF(LEN(Screening!B3)=0,"MISSING",IF(OR(NOT(ISNUMBER(Screening!B3)),COUNTIF($F$48:$F$282,Screening!B3)<>1),"INVALID",IF(COUNTIF(Screening!$B$2:$B$236,Screening!B3)>1,"DUPLICATE","OK")))) -> OK | C49: =IF(AND(LEN(Screening!B3)=0,LEN(Screening!D3)=0),"",IF(AND(B49="OK",ISNUMBER(Screening!D3),Screening!C3="yes",Screening!F3<>"",COUNTIF(Sessions!$A$2:$A$21,Screening!I3)=1,Screening!E3<>"",Screening!G3<>"",Screening!H3=$B$16),"OK","REVIEW")) -> OK | D49: =IF(A49=Screening!A3,"OK","CHANGED") -> OK | F49: 2 | G49: =SUMIF(Screening!$B$2:$B$236,F49,$H$48:$H$282) -> 1 | H49: =IF(ISNUMBER(Screening!D3),1,0) -> 1
A50: 3 | B50: =IF(AND(LEN(Screening!B4)=0,LEN(Screening!D4)=0),"",IF(LEN(Screening!B4)=0,"MISSING",IF(OR(NOT(ISNUMBER(Screening!B4)),COUNTIF($F$48:$F$282,Screening!B4)<>1),"INVALID",IF(COUNTIF(Screening!$B$2:$B$236,Screening!B4)>1,"DUPLICATE","OK")))) -> OK | C50: =IF(AND(LEN(Screening!B4)=0,LEN(Screening!D4)=0),"",IF(AND(B50="OK",ISNUMBER(Screening!D4),Screening!C4="yes",Screening!F4<>"",COUNTIF(Sessions!$A$2:$A$21,Screening!I4)=1,Screening!E4<>"",Screening!G4<>"",Screening!H4=$B$16),"OK","REVIEW")) -> OK | D50: =IF(A50=Screening!A4,"OK","CHANGED") -> OK | F50: 3 | G50: =SUMIF(Screening!$B$2:$B$236,F50,$H$48:$H$282) -> 1 | H50: =IF(ISNUMBER(Screening!D4),1,0) -> 1
A51: 4 | B51: =IF(AND(LEN(Screening!B5)=0,LEN(Screening!D5)=0),"",IF(LEN(Screening!B5)=0,"MISSING",IF(OR(NOT(ISNUMBER(Screening!B5)),COUNTIF($F$48:$F$282,Screening!B5)<>1),"INVALID",IF(COUNTIF(Screening!$B$2:$B$236,Screening!B5)>1,"DUPLICATE","OK")))) -> OK | C51: =IF(AND(LEN(Screening!B5)=0,LEN(Screening!D5)=0),"",IF(AND(B51="OK",ISNUMBER(Screening!D5),Screening!C5="yes",Screening!F5<>"",COUNTIF(Sessions!$A$2:$A$21,Screening!I5)=1,Screening!E5<>"",Screening!G5<>"",Screening!H5=$B$16),"OK","REVIEW")) -> OK | D51: =IF(A51=Screening!A5,"OK","CHANGED") -> OK | F51: 4 | G51: =SUMIF(Screening!$B$2:$B$236,F51,$H$48:$H$282) -> 1 | H51: =IF(ISNUMBER(Screening!D5),1,0) -> 1
A52: 5 | B52: =IF(AND(LEN(Screening!B6)=0,LEN(Screening!D6)=0),"",IF(LEN(Screening!B6)=0,"MISSING",IF(OR(NOT(ISNUMBER(Screening!B6)),COUNTIF($F$48:$F$282,Screening!B6)<>1),"INVALID",IF(COUNTIF(Screening!$B$2:$B$236,Screening!B6)>1,"DUPLICATE","OK")))) -> OK | C52: =IF(AND(LEN(Screening!B6)=0,LEN(Screening!D6)=0),"",IF(AND(B52="OK",ISNUMBER(Screening!D6),Screening!C6="yes",Screening!F6<>"",COUNTIF(Sessions!$A$2:$A$21,Screening!I6)=1,Screening!E6<>"",Screening!G6<>"",Screening!H6=$B$16),"OK","REVIEW")) -> OK | D52: =IF(A52=Screening!A6,"OK","CHANGED") -> OK | F52: 5 | G52: =SUMIF(Screening!$B$2:$B$236,F52,$H$48:$H$282) -> 1 | H52: =IF(ISNUMBER(Screening!D6),1,0) -> 1
...

Sheet Screening
A1: screening_sequence | B1: part_id | C1: laser_etched_id_verified | D1: screening_reading_in | E1: screening_date | F1: screening_time | G1: screening_operator | H1: caliper_serial_number | I1: session_id | J1: pre_session_reference_mean_in | K1: post_session_reference_mean_in | L1: screening_class | M1: selected_for_validation | N1: selection_stratum | O1: repeat_required | P1: notes
A2: 1 | B2: 178 | C2: yes | D2: 0.996 | E2: =IF(OR($I2="",$D2=""),"",IFERROR(IF(VLOOKUP($I2,Sessions!$A$2:$W$21,2,FALSE)="","",VLOOKUP($I2,Sessions!$A$2:$W$21,2,FALSE)),"")) -> 46268 | F2: 0.73263889 | G2: =IF(OR($I2="",$D2=""),"",IFERROR(IF(VLOOKUP($I2,Sessions!$A$2:$W$21,5,FALSE)="","",VLOOKUP($I2,Sessions!$A$2:$W$21,5,FALSE)),"")) -> Timmy D. Bell | H2: B24254849 | I2: 1 | J2: =IF(OR($I2="",$D2=""),"",IFERROR(IF(VLOOKUP($I2,Sessions!$A$2:$W$21,13,FALSE)="","",VLOOKUP($I2,Sessions!$A$2:$W$21,13,FALSE)),"")) -> 1 | K2: =IF(OR($I2="",$D2=""),"",IFERROR(IF(VLOOKUP($I2,Sessions!$A$2:$W$21,20,FALSE)="","",VLOOKUP($I2,Sessions!$A$2:$W$21,20,FALSE)),"")) -> 1
A3: 2 | B3: 187 | C3: yes | D3: 0.9995 | E3: =IF(OR($I3="",$D3=""),"",IFERROR(IF(VLOOKUP($I3,Sessions!$A$2:$W$21,2,FALSE)="","",VLOOKUP($I3,Sessions!$A$2:$W$21,2,FALSE)),"")) -> 46268 | F3: 0.73333333 | G3: =IF(OR($I3="",$D3=""),"",IFERROR(IF(VLOOKUP($I3,Sessions!$A$2:$W$21,5,FALSE)="","",VLOOKUP($I3,Sessions!$A$2:$W$21,5,FALSE)),"")) -> Timmy D. Bell | H3: B24254849 | I3: 1 | J3: =IF(OR($I3="",$D3=""),"",IFERROR(IF(VLOOKUP($I3,Sessions!$A$2:$W$21,13,FALSE)="","",VLOOKUP($I3,Sessions!$A$2:$W$21,13,FALSE)),"")) -> 1 | K3: =IF(OR($I3="",$D3=""),"",IFERROR(IF(VLOOKUP($I3,Sessions!$A$2:$W$21,20,FALSE)="","",VLOOKUP($I3,Sessions!$A$2:$W$21,20,FALSE)),"")) -> 1
A4: 3 | B4: 121 | C4: yes | D4: 0.9995 | E4: =IF(OR($I4="",$D4=""),"",IFERROR(IF(VLOOKUP($I4,Sessions!$A$2:$W$21,2,FALSE)="","",VLOOKUP($I4,Sessions!$A$2:$W$21,2,FALSE)),"")) -> 46268 | F4: 0.73541667 | G4: =IF(OR($I4="",$D4=""),"",IFERROR(IF(VLOOKUP($I4,Sessions!$A$2:$W$21,5,FALSE)="","",VLOOKUP($I4,Sessions!$A$2:$W$21,5,FALSE)),"")) -> Timmy D. Bell | H4: B24254849 | I4: 1 | J4: =IF(OR($I4="",$D4=""),"",IFERROR(IF(VLOOKUP($I4,Sessions!$A$2:$W$21,13,FALSE)="","",VLOOKUP($I4,Sessions!$A$2:$W$21,13,FALSE)),"")) -> 1 | K4: =IF(OR($I4="",$D4=""),"",IFERROR(IF(VLOOKUP($I4,Sessions!$A$2:$W$21,20,FALSE)="","",VLOOKUP($I4,Sessions!$A$2:$W$21,20,FALSE)),"")) -> 1
A5: 4 | B5: 197 | C5: yes | D5: 0.9985 | E5: =IF(OR($I5="",$D5=""),"",IFERROR(IF(VLOOKUP($I5,Sessions!$A$2:$W$21,2,FALSE)="","",VLOOKUP($I5,Sessions!$A$2:$W$21,2,FALSE)),"")) -> 46268 | F5: 0.73541667 | G5: =IF(OR($I5="",$D5=""),"",IFERROR(IF(VLOOKUP($I5,Sessions!$A$2:$W$21,5,FALSE)="","",VLOOKUP($I5,Sessions!$A$2:$W$21,5,FALSE)),"")) -> Timmy D. Bell | H5: B24254849 | I5: 1 | J5: =IF(OR($I5="",$D5=""),"",IFERROR(IF(VLOOKUP($I5,Sessions!$A$2:$W$21,13,FALSE)="","",VLOOKUP($I5,Sessions!$A$2:$W$21,13,FALSE)),"")) -> 1 | K5: =IF(OR($I5="",$D5=""),"",IFERROR(IF(VLOOKUP($I5,Sessions!$A$2:$W$21,20,FALSE)="","",VLOOKUP($I5,Sessions!$A$2:$W$21,20,FALSE)),"")) -> 1
A6: 5 | B6: 86 | C6: yes | D6: 1.0085 | E6: =IF(OR($I6="",$D6=""),"",IFERROR(IF(VLOOKUP($I6,Sessions!$A$2:$W$21,2,FALSE)="","",VLOOKUP($I6,Sessions!$A$2:$W$21,2,FALSE)),"")) -> 46268 | F6: 0.73541667 | G6: =IF(OR($I6="",$D6=""),"",IFERROR(IF(VLOOKUP($I6,Sessions!$A$2:$W$21,5,FALSE)="","",VLOOKUP($I6,Sessions!$A$2:$W$21,5,FALSE)),"")) -> Timmy D. Bell | H6: B24254849 | I6: 1 | J6: =IF(OR($I6="",$D6=""),"",IFERROR(IF(VLOOKUP($I6,Sessions!$A$2:$W$21,13,FALSE)="","",VLOOKUP($I6,Sessions!$A$2:$W$21,13,FALSE)),"")) -> 1 | K6: =IF(OR($I6="",$D6=""),"",IFERROR(IF(VLOOKUP($I6,Sessions!$A$2:$W$21,20,FALSE)="","",VLOOKUP($I6,Sessions!$A$2:$W$21,20,FALSE)),"")) -> 1
A7: 6 | B7: 186 | C7: yes | D7: 1.002 | E7: =IF(OR($I7="",$D7=""),"",IFERROR(IF(VLOOKUP($I7,Sessions!$A$2:$W$21,2,FALSE)="","",VLOOKUP($I7,Sessions!$A$2:$W$21,2,FALSE)),"")) -> 46268 | F7: 0.73541667 | G7: =IF(OR($I7="",$D7=""),"",IFERROR(IF(VLOOKUP($I7,Sessions!$A$2:$W$21,5,FALSE)="","",VLOOKUP($I7,Sessions!$A$2:$W$21,5,FALSE)),"")) -> Timmy D. Bell | H7: B24254849 | I7: 1 | J7: =IF(OR($I7="",$D7=""),"",IFERROR(IF(VLOOKUP($I7,Sessions!$A$2:$W$21,13,FALSE)="","",VLOOKUP($I7,Sessions!$A$2:$W$21,13,FALSE)),"")) -> 1 | K7: =IF(OR($I7="",$D7=""),"",IFERROR(IF(VLOOKUP($I7,Sessions!$A$2:$W$21,20,FALSE)="","",VLOOKUP($I7,Sessions!$A$2:$W$21,20,FALSE)),"")) -> 1
A8: 7 | B8: 234 | C8: yes | D8: 0.9905 | E8: =IF(OR($I8="",$D8=""),"",IFERROR(IF(VLOOKUP($I8,Sessions!$A$2:$W$21,2,FALSE)="","",VLOOKUP($I8,Sessions!$A$2:$W$21,2,FALSE)),"")) -> 46268 | F8: 0.73541667 | G8: =IF(OR($I8="",$D8=""),"",IFERROR(IF(VLOOKUP($I8,Sessions!$A$2:$W$21,5,FALSE)="","",VLOOKUP($I8,Sessions!$A$2:$W$21,5,FALSE)),"")) -> Timmy D. Bell | H8: B24254849 | I8: 1 | J8: =IF(OR($I8="",$D8=""),"",IFERROR(IF(VLOOKUP($I8,Sessions!$A$2:$W$21,13,FALSE)="","",VLOOKUP($I8,Sessions!$A$2:$W$21,13,FALSE)),"")) -> 1 | K8: =IF(OR($I8="",$D8=""),"",IFERROR(IF(VLOOKUP($I8,Sessions!$A$2:$W$21,20,FALSE)="","",VLOOKUP($I8,Sessions!$A$2:$W$21,20,FALSE)),"")) -> 1
A9: 8 | B9: 193 | C9: yes | D9: 1.0085 | E9: =IF(OR($I9="",$D9=""),"",IFERROR(IF(VLOOKUP($I9,Sessions!$A$2:$W$21,2,FALSE)="","",VLOOKUP($I9,Sessions!$A$2:$W$21,2,FALSE)),"")) -> 46268 | F9: 0.73541667 | G9: =IF(OR($I9="",$D9=""),"",IFERROR(IF(VLOOKUP($I9,Sessions!$A$2:$W$21,5,FALSE)="","",VLOOKUP($I9,Sessions!$A$2:$W$21,5,FALSE)),"")) -> Timmy D. Bell | H9: B24254849 | I9: 1 | J9: =IF(OR($I9="",$D9=""),"",IFERROR(IF(VLOOKUP($I9,Sessions!$A$2:$W$21,13,FALSE)="","",VLOOKUP($I9,Sessions!$A$2:$W$21,13,FALSE)),"")) -> 1 | K9: =IF(OR($I9="",$D9=""),"",IFERROR(IF(VLOOKUP($I9,Sessions!$A$2:$W$21,20,FALSE)="","",VLOOKUP($I9,Sessions!$A$2:$W$21,20,FALSE)),"")) -> 1
A10: 9 | B10: 214 | C10: yes | D10: 0.9995 | E10: =IF(OR($I10="",$D10=""),"",IFERROR(IF(VLOOKUP($I10,Sessions!$A$2:$W$21,2,FALSE)="","",VLOOKUP($I10,Sessions!$A$2:$W$21,2,FALSE)),"")) -> 46268 | F10: 0.73611111 | G10: =IF(OR($I10="",$D10=""),"",IFERROR(IF(VLOOKUP($I10,Sessions!$A$2:$W$21,5,FALSE)="","",VLOOKUP($I10,Sessions!$A$2:$W$21,5,FALSE)),"")) -> Timmy D. Bell | H10: B24254849 | I10: 1 | J10: =IF(OR($I10="",$D10=""),"",IFERROR(IF(VLOOKUP($I10,Sessions!$A$2:$W$21,13,FALSE)="","",VLOOKUP($I10,Sessions!$A$2:$W$21,13,FALSE)),"")) -> 1 | K10: =IF(OR($I10="",$D10=""),"",IFERROR(IF(VLOOKUP($I10,Sessions!$A$2:$W$21,20,FALSE)="","",VLOOKUP($I10,Sessions!$A$2:$W$21,20,FALSE)),"")) -> 1
A11: 10 | B11: 139 | C11: yes | D11: 0.9985 | E11: =IF(OR($I11="",$D11=""),"",IFERROR(IF(VLOOKUP($I11,Sessions!$A$2:$W$21,2,FALSE)="","",VLOOKUP($I11,Sessions!$A$2:$W$21,2,FALSE)),"")) -> 46268 | F11: 0.73611111 | G11: =IF(OR($I11="",$D11=""),"",IFERROR(IF(VLOOKUP($I11,Sessions!$A$2:$W$21,5,FALSE)="","",VLOOKUP($I11,Sessions!$A$2:$W$21,5,FALSE)),"")) -> Timmy D. Bell | H11: B24254849 | I11: 1 | J11: =IF(OR($I11="",$D11=""),"",IFERROR(IF(VLOOKUP($I11,Sessions!$A$2:$W$21,13,FALSE)="","",VLOOKUP($I11,Sessions!$A$2:$W$21,13,FALSE)),"")) -> 1 | K11: =IF(OR($I11="",$D11=""),"",IFERROR(IF(VLOOKUP($I11,Sessions!$A$2:$W$21,20,FALSE)="","",VLOOKUP($I11,Sessions!$A$2:$W$21,20,FALSE)),"")) -> 1
A12: 11 | B12: 231 | C12: yes | D12: 0.9915 | E12: =IF(OR($I12="",$D12=""),"",IFERROR(IF(VLOOKUP($I12,Sessions!$A$2:$W$21,2,FALSE)="","",VLOOKUP($I12,Sessions!$A$2:$W$21,2,FALSE)),"")) -> 46268 | F12: 0.73680556 | G12: =IF(OR($I12="",$D12=""),"",IFERROR(IF(VLOOKUP($I12,Sessions!$A$2:$W$21,5,FALSE)="","",VLOOKUP($I12,Sessions!$A$2:$W$21,5,FALSE)),"")) -> Timmy D. Bell | H12: B24254849 | I12: 1 | J12: =IF(OR($I12="",$D12=""),"",IFERROR(IF(VLOOKUP($I12,Sessions!$A$2:$W$21,13,FALSE)="","",VLOOKUP($I12,Sessions!$A$2:$W$21,13,FALSE)),"")) -> 1 | K12: =IF(OR($I12="",$D12=""),"",IFERROR(IF(VLOOKUP($I12,Sessions!$A$2:$W$21,20,FALSE)="","",VLOOKUP($I12,Sessions!$A$2:$W$21,20,FALSE)),"")) -> 1
A13: 12 | B13: 138 | C13: yes | D13: 0.991 | E13: =IF(OR($I13="",$D13=""),"",IFERROR(IF(VLOOKUP($I13,Sessions!$A$2:$W$21,2,FALSE)="","",VLOOKUP($I13,Sessions!$A$2:$W$21,2,FALSE)),"")) -> 46268 | F13: 0.73680556 | G13: =IF(OR($I13="",$D13=""),"",IFERROR(IF(VLOOKUP($I13,Sessions!$A$2:$W$21,5,FALSE)="","",VLOOKUP($I13,Sessions!$A$2:$W$21,5,FALSE)),"")) -> Timmy D. Bell | H13: B24254849 | I13: 1 | J13: =IF(OR($I13="",$D13=""),"",IFERROR(IF(VLOOKUP($I13,Sessions!$A$2:$W$21,13,FALSE)="","",VLOOKUP($I13,Sessions!$A$2:$W$21,13,FALSE)),"")) -> 1 | K13: =IF(OR($I13="",$D13=""),"",IFERROR(IF(VLOOKUP($I13,Sessions!$A$2:$W$21,20,FALSE)="","",VLOOKUP($I13,Sessions!$A$2:$W$21,20,FALSE)),"")) -> 1
... A236: 235 | B236: 146 | C236: yes | D236: 0.9915 | E236: =IF(OR($I236="",$D236=""),"",IFERROR(IF(VLOOKUP($I236,Sessions!$A$2:$W$21,2,FALSE)="","",VLOOKUP($I236,Sessions!$A$2:$W$21,2,FALSE)),"")) -> 46268 | F236: 0.79305556 | G236: =IF(OR($I236="",$D236=""),"",IFERROR(IF(VLOOKUP($I236,Sessions!$A$2:$W$21,5,FALSE)="","",VLOOKUP($I236,Sessions!$A$2:$W$21,5,FALSE)),"")) -> Timmy D. Bell | H236: B24254849 | I236: 1 | J236: =IF(OR($I236="",$D236=""),"",IFERROR(IF(VLOOKUP($I236,Sessions!$A$2:$W$21,13,FALSE)="","",VLOOKUP($I236,Sessions!$A$2:$W$21,13,FALSE)),"")) -> 1 | K236: =IF(OR($I236="",$D236=""),"",IFERROR(IF(VLOOKUP($I236,Sessions!$A$2:$W$21,20,FALSE)="","",VLOOKUP($I236,Sessions!$A$2:$W$21,20,FALSE)),"")) -> 1

Sheet Sessions
A1: session_id | B1: session_date | C1: session_start_time | D1: session_end_time | E1: operator | F1: caliper_serial_number | G1: reference_standard_in | H1: pre_1_in | I1: pre_2_in | J1: pre_3_in | K1: pre_4_in | L1: pre_5_in | M1: pre_mean_in | N1: pre_range_in | O1: post_1_in | P1: post_2_in | Q1: post_3_in | R1: post_4_in | S1: post_5_in | T1: post_mean_in | U1: post_range_in | V1: session_status | W1: notes
A2: 1 | B2: 46268 | C2: 5:21 PM | D2: 7:38 PM | E2: =IF(A2="","",Start!$B$15) -> Timmy D. Bell | F2: =IF(A2="","",Start!$B$16) -> B24254849 | G2: =IF(A2="","",Start!$B$17) -> 1.0000024 | H2: 1 | I2: 1 | J2: 1 | K2: 1 | L2: 1 | M2: =IF(COUNT(H2:L2)=Start!$B$22,AVERAGE(H2:L2),"") -> 1 | N2: =IF(COUNT(H2:L2)=Start!$B$22,MAX(H2:L2)-MIN(H2:L2),"") -> 0 | O2: 1 | P2: 1 | Q2: 1 | R2: 1 | S2: 1 | T2: =IF(COUNT(O2:S2)=Start!$B$22,AVERAGE(O2:S2),"") -> 1 | U2: =IF(COUNT(O2:S2)=Start!$B$22,MAX(O2:S2)-MIN(O2:S2),"") -> 0 | W2: Before case screening, after pre-check: room 73.7 F at 2026-09-03T17:27:24-05:00; gauge-block surface 74.4 F at 2026-09-03T17:28:58-05:00. Post-session: Room temperature: 74.4 F at 2026-09-03T19:36:29-05:00 Gauge-block surface temperature: 74.7 F at 2026-09-03T19:38:16-05:00 Temperature readings settled: yes Caliper closed-jaw zero: 0.0000 in Equipment/environmental abnormalities: none Measurement issues or interruptions: none Final session disposition: pending review
E3: =IF(A3="","",Start!$B$15) | F3: =IF(A3="","",Start!$B$16) | G3: =IF(A3="","",Start!$B$17) | M3: =IF(COUNT(H3:L3)=Start!$B$22,AVERAGE(H3:L3),"") | N3: =IF(COUNT(H3:L3)=Start!$B$22,MAX(H3:L3)-MIN(H3:L3),"") | T3: =IF(COUNT(O3:S3)=Start!$B$22,AVERAGE(O3:S3),"") | U3: =IF(COUNT(O3:S3)=Start!$B$22,MAX(O3:S3)-MIN(O3:S3),"")
E4: =IF(A4="","",Start!$B$15) | F4: =IF(A4="","",Start!$B$16) | G4: =IF(A4="","",Start!$B$17) | M4: =IF(COUNT(H4:L4)=Start!$B$22,AVERAGE(H4:L4),"") | N4: =IF(COUNT(H4:L4)=Start!$B$22,MAX(H4:L4)-MIN(H4:L4),"") | T4: =IF(COUNT(O4:S4)=Start!$B$22,AVERAGE(O4:S4),"") | U4: =IF(COUNT(O4:S4)=Start!$B$22,MAX(O4:S4)-MIN(O4:S4),"")
E5: =IF(A5="","",Start!$B$15) | F5: =IF(A5="","",Start!$B$16) | G5: =IF(A5="","",Start!$B$17) | M5: =IF(COUNT(H5:L5)=Start!$B$22,AVERAGE(H5:L5),"") | N5: =IF(COUNT(H5:L5)=Start!$B$22,MAX(H5:L5)-MIN(H5:L5),"") | T5: =IF(COUNT(O5:S5)=Start!$B$22,AVERAGE(O5:S5),"") | U5: =IF(COUNT(O5:S5)=Start!$B$22,MAX(O5:S5)-MIN(O5:S5),"")
E6: =IF(A6="","",Start!$B$15) | F6: =IF(A6="","",Start!$B$16) | G6: =IF(A6="","",Start!$B$17) | M6: =IF(COUNT(H6:L6)=Start!$B$22,AVERAGE(H6:L6),"") | N6: =IF(COUNT(H6:L6)=Start!$B$22,MAX(H6:L6)-MIN(H6:L6),"") | T6: =IF(COUNT(O6:S6)=Start!$B$22,AVERAGE(O6:S6),"") | U6: =IF(COUNT(O6:S6)=Start!$B$22,MAX(O6:S6)-MIN(O6:S6),"")
E7: =IF(A7="","",Start!$B$15) | F7: =IF(A7="","",Start!$B$16) | G7: =IF(A7="","",Start!$B$17) | M7: =IF(COUNT(H7:L7)=Start!$B$22,AVERAGE(H7:L7),"") | N7: =IF(COUNT(H7:L7)=Start!$B$22,MAX(H7:L7)-MIN(H7:L7),"") | T7: =IF(COUNT(O7:S7)=Start!$B$22,AVERAGE(O7:S7),"") | U7: =IF(COUNT(O7:S7)=Start!$B$22,MAX(O7:S7)-MIN(O7:S7),"")
E8: =IF(A8="","",Start!$B$15) | F8: =IF(A8="","",Start!$B$16) | G8: =IF(A8="","",Start!$B$17) | M8: =IF(COUNT(H8:L8)=Start!$B$22,AVERAGE(H8:L8),"") | N8: =IF(COUNT(H8:L8)=Start!$B$22,MAX(H8:L8)-MIN(H8:L8),"") | T8: =IF(COUNT(O8:S8)=Start!$B$22,AVERAGE(O8:S8),"") | U8: =IF(COUNT(O8:S8)=Start!$B$22,MAX(O8:S8)-MIN(O8:S8),"")
E9: =IF(A9="","",Start!$B$15) | F9: =IF(A9="","",Start!$B$16) | G9: =IF(A9="","",Start!$B$17) | M9: =IF(COUNT(H9:L9)=Start!$B$22,AVERAGE(H9:L9),"") | N9: =IF(COUNT(H9:L9)=Start!$B$22,MAX(H9:L9)-MIN(H9:L9),"") | T9: =IF(COUNT(O9:S9)=Start!$B$22,AVERAGE(O9:S9),"") | U9: =IF(COUNT(O9:S9)=Start!$B$22,MAX(O9:S9)-MIN(O9:S9),"")
E10: =IF(A10="","",Start!$B$15) | F10: =IF(A10="","",Start!$B$16) | G10: =IF(A10="","",Start!$B$17) | M10: =IF(COUNT(H10:L10)=Start!$B$22,AVERAGE(H10:L10),"") | N10: =IF(COUNT(H10:L10)=Start!$B$22,MAX(H10:L10)-MIN(H10:L10),"") | T10: =IF(COUNT(O10:S10)=Start!$B$22,AVERAGE(O10:S10),"") | U10: =IF(COUNT(O10:S10)=Start!$B$22,MAX(O10:S10)-MIN(O10:S10),"")
E11: =IF(A11="","",Start!$B$15) | F11: =IF(A11="","",Start!$B$16) | G11: =IF(A11="","",Start!$B$17) | M11: =IF(COUNT(H11:L11)=Start!$B$22,AVERAGE(H11:L11),"") | N11: =IF(COUNT(H11:L11)=Start!$B$22,MAX(H11:L11)-MIN(H11:L11),"") | T11: =IF(COUNT(O11:S11)=Start!$B$22,AVERAGE(O11:S11),"") | U11: =IF(COUNT(O11:S11)=Start!$B$22,MAX(O11:S11)-MIN(O11:S11),"")
E12: =IF(A12="","",Start!$B$15) | F12: =IF(A12="","",Start!$B$16) | G12: =IF(A12="","",Start!$B$17) | M12: =IF(COUNT(H12:L12)=Start!$B$22,AVERAGE(H12:L12),"") | N12: =IF(COUNT(H12:L12)=Start!$B$22,MAX(H12:L12)-MIN(H12:L12),"") | T12: =IF(COUNT(O12:S12)=Start!$B$22,AVERAGE(O12:S12),"") | U12: =IF(COUNT(O12:S12)=Start!$B$22,MAX(O12:S12)-MIN(O12:S12),"")
E13: =IF(A13="","",Start!$B$15) | F13: =IF(A13="","",Start!$B$16) | G13: =IF(A13="","",Start!$B$17) | M13: =IF(COUNT(H13:L13)=Start!$B$22,AVERAGE(H13:L13),"") | N13: =IF(COUNT(H13:L13)=Start!$B$22,MAX(H13:L13)-MIN(H13:L13),"") | T13: =IF(COUNT(O13:S13)=Start!$B$22,AVERAGE(O13:S13),"") | U13: =IF(COUNT(O13:S13)=Start!$B$22,MAX(O13:S13)-MIN(O13:S13),"")
E14: =IF(A14="","",Start!$B$15) | F14: =IF(A14="","",Start!$B$16) | G14: =IF(A14="","",Start!$B$17) | M14: =IF(COUNT(H14:L14)=Start!$B$22,AVERAGE(H14:L14),"") | N14: =IF(COUNT(H14:L14)=Start!$B$22,MAX(H14:L14)-MIN(H14:L14),"") | T14: =IF(COUNT(O14:S14)=Start!$B$22,AVERAGE(O14:S14),"") | U14: =IF(COUNT(O14:S14)=Start!$B$22,MAX(O14:S14)-MIN(O14:S14),"")
... E21: =IF(A21="","",Start!$B$15) | F21: =IF(A21="","",Start!$B$16) | G21: =IF(A21="","",Start!$B$17) | M21: =IF(COUNT(H21:L21)=Start!$B$22,AVERAGE(H21:L21),"") | N21: =IF(COUNT(H21:L21)=Start!$B$22,MAX(H21:L21)-MIN(H21:L21),"") | T21: =IF(COUNT(O21:S21)=Start!$B$22,AVERAGE(O21:S21),"") | U21: =IF(COUNT(O21:S21)=Start!$B$22,MAX(O21:S21)-MIN(O21:S21),"")
